I'm sorry, but an uncaught exception occurred.

While running game code:
  File "game/script4.rpy", line 81, in script
    a "He's just free loading. Maybe we should have worked with Harold."
Exception: Image 'harold surprised' does not accept attributes 'in left'.

-- Full Traceback ------------------------------------------------------------

Full traceback:
  File "game/script4.rpy", line 81, in script
    a "He's just free loading. Maybe we should have worked with Harold."
  File "D:\Library\Downloads\renpy-8.0.3-sdk\renpy\ast.py", line 1408, in execute
    show_imspec(self.imspec, atl=getattr(self, "atl", None))
  File "D:\Library\Downloads\renpy-8.0.3-sdk\renpy\ast.py", line 1371, in show_imspec
    renpy.config.show(name,
  File "D:\Library\Downloads\renpy-8.0.3-sdk\renpy\exports.py", line 686, in show
    if not base.find_target() and renpy.config.missing_show:
  File "D:\Library\Downloads\renpy-8.0.3-sdk\renpy\display\image.py", line 414, in find_target
    self.target = target._duplicate(a)
  File "D:\Library\Downloads\renpy-8.0.3-sdk\renpy\display\core.py", line 397, in _duplicate
    args.extraneous()
  File "D:\Library\Downloads\renpy-8.0.3-sdk\renpy\display\core.py", line 265, in extraneous
    raise Exception("Image '{}' does not accept attributes '{}'.".format(
Exception: Image 'harold surprised' does not accept attributes 'in left'.

Windows-10-10.0.19045 AMD64
Ren'Py 8.0.3.22090809
Final Project 1.0
Thu May  4 12:01:15 2023
